{
  "Header": {
    "Original": "CVE-2025-32873 (An issue was discovered in Django 4.2 before 4.2.21, 5.1 before 5.1.9, ...)",
    "ID": "CVE-2025-32873",
    "Description": "(An issue was discovered in Django 4.2 before 4.2.21, 5.1 before 5.1.9, ...)"
  },
  "Annotations": [
    {
      "Original": "{DLA-4210-1}",
      "Type": "xref",
      "Bugs": [
        "DLA-4210-1"
      ]
    },
    {
      "Original": "- python-django 3:4.2.21-1 (bug #1104872)",
      "Type": "package",
      "Package": "python-django",
      "Kind": "fixed",
      "Version": "3:4.2.21-1",
      "BugNo": 1104872
    },
    {
      "Original": "NOTE: https://www.djangoproject.com/weblog/2025/may/07/security-releases/",
      "Type": "NOTE",
      "Description": "https://www.djangoproject.com/weblog/2025/may/07/security-releases/"
    },
    {
      "Original": "NOTE: Fixed by: https://github.com/django/django/commit/9cd8028f3e38dca8e51c1388f474eecbe7d6ca3c (4.2.21)",
      "Type": "NOTE",
      "Description": "Fixed by: https://github.com/django/django/commit/9cd8028f3e38dca8e51c1388f474eecbe7d6ca3c (4.2.21)"
    }
  ]
}