{
  "Header": {
    "Original": "CVE-2025-48432 (An issue was discovered in Django 5.2 before 5.2.3, 5.1 before 5.1.11, ...)",
    "ID": "CVE-2025-48432",
    "Description": "(An issue was discovered in Django 5.2 before 5.2.3, 5.1 before 5.1.11, ...)"
  },
  "Annotations": [
    {
      "Original": "{DLA-4210-1}",
      "Type": "xref",
      "Bugs": [
        "DLA-4210-1"
      ]
    },
    {
      "Original": "- python-django 3:4.2.23-1 (bug #1107282; bug #1107616)",
      "Type": "package",
      "Package": "python-django",
      "Kind": "fixed",
      "Version": "3:4.2.23-1",
      "BugNo": 1107616
    },
    {
      "Original": "NOTE: https://www.djangoproject.com/weblog/2025/jun/04/security-releases/",
      "Type": "NOTE",
      "Description": "https://www.djangoproject.com/weblog/2025/jun/04/security-releases/"
    },
    {
      "Original": "NOTE: Fixed by: https://github.com/django/django/commit/ac03c5e7df8680c61cdb0d3bdb8be9095dba841e (4.2.22)",
      "Type": "NOTE",
      "Description": "Fixed by: https://github.com/django/django/commit/ac03c5e7df8680c61cdb0d3bdb8be9095dba841e (4.2.22)"
    },
    {
      "Original": "NOTE: Initial 4.2.22 release didn't fix it fully: https://www.djangoproject.com/weblog/2025/jun/10/bugfix-releases/",
      "Type": "NOTE",
      "Description": "Initial 4.2.22 release didn't fix it fully: https://www.djangoproject.com/weblog/2025/jun/10/bugfix-releases/"
    },
    {
      "Original": "NOTE: Follow up: https://github.com/django/django/commit/b597d46bb19c8567615e62029210dab16c70db7d (4.2.23)",
      "Type": "NOTE",
      "Description": "Follow up: https://github.com/django/django/commit/b597d46bb19c8567615e62029210dab16c70db7d (4.2.23)"
    }
  ]
}